Workbook

Sheet RANGO
E2: RANGO IP DE LAS AREAS DEL IMJUVE
E3: ÁREA DE ASIGNACIÓN | F3: RANGO DE IP´S | H3: LIBRES | I3: OCUPADAS | J3: EN CONFLICTO | K3: TOTAL, DE IP´S | L3: % USADO
E4: DIRECCIÓN GENERAL | F4: 172.17.0.5 | G4: 172.17.0.18 | H4: =DG!E20 -> 1 | I4: =DG!F20 -> 13 | J4: =DG!G20 -> 0 | K4: =DG!H20 -> 14 | L4: =I4/K4 -> 0.92857143
E5: =DATOS!B3 -> DIRECCIÓN DE BIENESTAR Y ESTIMULOS A LA JUVENTUD | F5: 172.17.0.19 | G5: 172.17.0.99 | H5: =DBEJ!E89 -> 49 | I5: =DBEJ!F89 -> 32 | J5: =DBEJ!G89 -> 0 | K5: =DBEJ!H89 -> 81 | L5: =I5/K5 -> 0.39506173
E6: =DATOS!B4 -> DIRECCIÓN DE INESTIGACIÓN Y ESTUDIOS SOBRE JUVENTUDES | F6: 172.17.0.100 | G6: 172.17.0.157 | H6: =DIEJ!E64 -> 43 | I6: =DIEJ!F64 -> 15 | J6: =DIEJ!G64 -> 0 | K6: =DIEJ!H64 -> 58 | L6: =I6/K6 -> 0.25862069
E7: =DATOS!B5 -> DIRECCIÓN DE COORDINACIÓN SERCTORIAL Y REGIONAL | F7: 172.17.0.158 | G7: 172.17.0.205 | H7: =DCSR!E53 -> 35 | I7: =DCSR!F53 -> 13 | J7: =DCSR!G53 -> 0 | K7: =DCSR!H53 -> 48 | L7: =I7/K7 -> 0.27083333
E8: =DATOS!B6 -> DIRECCIÓN DE EVALUACIÓN Y CONTROL | F8: 172.17.0.206 | G8: 172.17.0.242 | H8: =DEC!E42 -> 24 | I8: =DEC!F42 -> 13 | J8: =DEC!G42 -> 0 | K8: =DEC!H42 -> 37 | L8: =I8/K8 -> 0.35135135
E9: =DATOS!B7 -> DIRECCIÓN DE FINANZAS | F9: 172.17.0.243 | G9: 172.17.1.22 | H9: =DF!E39 -> 14 | I9: =DF!F39 -> 20 | J9: =DF!G39 -> 0 | K9: =DF!H39 -> 34 | L9: =I9/K9 -> 0.58823529
E10: =DATOS!B8 -> DIRECCIÓN DE RECURSOS HUMANOS Y MATERIALES | F10: 172.17.1.23 | G10: 172.17.1.84 | H10: =DRHM!E67 -> 29 | I10: =DRHM!F67 -> 32 | J10: =DRHM!G67 -> 1 | K10: =DRHM!H67 -> 62 | L10: =I10/K10 -> 0.51612903
E11: =DATOS!B9 -> DIRECCIÓN DE ASUSTOS JURÍDICOS | F11: 172.17.1.85 | G11: 172.17.1.103 | H11: =DAJ!E24 -> 12 | I11: =DAJ!F24 -> 7 | J11: =DAJ!G24 -> 0 | K11: =DAJ!H24 -> 19 | L11: =I11/K11 -> 0.36842105
E12: =DATOS!B10 -> DIRECCIÓN DE COMUNICACIÓN SOCIAL | F12: 172.17.1.104 | G12: 172.17.1.142 | H12: =DCS!E44 -> 21 | I12: =DCS!F44 -> 18 | J12: =DCS!G44 -> 0 | K12: =DCS!H44 -> 39 | L12: =I12/K12 -> 0.46153846
E13: =DATOS!B14 -> TITULAR DE AUDITORIA INTERNA Y QUEJAS | F13: 172.17.1.143 | G13: 172.17.1.160 | H13: =OIC!E23 -> 14 | I13: =OIC!F23 -> 4 | J13: =OIC!G23 -> 0 | K13: =OIC!H23 -> 18 | L13: =I13/K13 -> 0.22222222
E14: =DATOS!B12 -> SUBDIRECCIÓN DE SISTEMAS | F14: 172.17.1.161 | G14: 172.17.1.250 | H14: =SS!E95 -> 31 | I14: =SS!F95 -> 59 | J14: =SS!G95 -> 0 | K14: =SS!H95 -> 90 | L14: =I14/K14 -> 0.65555556
E15: Totales | H15: =SUM(H4:H14) -> 273 | I15: =SUM(I4:I14) -> 226 | J15: =SUM(J4:J14) -> 1 | K15: =SUM(H15:J15) -> 500 | L15: =I15/K15 -> 0.452

Sheet DG
A1: =RANGO!E4 -> DIRECCIÓN GENERAL
A2: No. | B2: IP | C2: Usuario o nombre del propietario | D2: Tipo de equipo | E2: Institucional o Personal | F2: Marca | G2: modelo | H2: Número de Serie | I2: MAC | J2: Tipo de Conexión | K2: Confguración de red | L2: Área | M2: Restricciones | N2: YOUTUBE | O2: VIMEO | P2: SPOTIFY | Q2: OTRO STREAMING | R2: FACEBOOK | S2: TIK TOK | T2: INSTAGRAM | U2: WHATSAPP WEB | V2: OTRA RED SOCIAL | W2: SITIOS GUBERNAMENTALES | X2: NOTICIAS | Y2: OTRO | Z2: Estatus | AA2: OBSERVACIONES
A3: 1 | B3: 172.17.0.5 | C3: xgranados | D3: LAP | E3: Personal | F3: OTRO | G3: / | H3: / | I3: 94-E2-3C-26-8D-74 | J3: INALÁMBRICO | K3: MANUAL | L3: DRHM | M3: Con/Rest | N3: Sí | O3: Sí | P3: Sí | Q3: NO | R3: Sí | S3: Sí | T3: Sí | U3: Sí | V3: s | W3: Sí | X3: Sí | Y3: SI | Z3: Ocupada | AA3: cambiar a DRHM
A4: 2 | B4: 172.17.0.6 | C4: Karla Perez | D4: LAP | E4: Personal | G4: MACBOOK | J4: INALÁMBRICO | K4: MANUAL | L4: DRHM | M4: Sin/Rest | Z4: Ocupada
A5: 3 | B5: 172.17.0.7 | C5: NROSALES | D5: PC | E5: Institucional | F5: DELL | G5: OPTIPLEX 3080 | H5: / | I5: B0-4F-13-01-B1-B2 | J5: ALÁMBRICO | K5: DHCP | L5: DG | M5: Con/Rest | N5: No | O5: NO | P5: No | Q5: NO | R5: No | S5: NO | T5: No | U5: Sí | V5: NO | W5: Sí | X5: No | Y5: NO | Z5: Ocupada
A6: 4 | B6: 172.17.0.8 | C6: DG | D6: CEL | E6: Personal | F6: OTRO | G6: / | H6: / | I6: / | J6: INALÁMBRICO | K6: MANUAL | L6: DG | M6: Sin/Rest | Z6: Ocupada
A7: 5 | B7: 172.17.0.9 | C7: DG_Abraham | D7: LAP | E7: Institucional | F7: DELL | G7: latitude3420 | H7: / | I7: 14:85:7F:FF:F1:4F | J7: INALÁMBRICO | K7: MANUAL | L7: DG | M7: Con/Rest | Z7: Ocupada
A8: 6 | B8: 172.17.0.10 | C8: stecnica | D8: PC | E8: Institucional | F8: DELL | G8: OPTIPLEX 7090 | H8: / | I8: D0:8E:79:05:23:B6 | J8: ALÁMBRICO | K8: MANUAL | L8: ST | M8: Con/Rest | Z8: Ocupada
A9: 7 | B9: 172.17.0.11 | Z9: Ocupada
A10: 8 | B10: 172.17.0.12 | C10: Alexa_DG | D10: ALEXA | E10: Personal | F10: OTRO | G10: Echoshow 5 | H10: / | I10: B0:4F:13:01:B1:B2 | J10: INALÁMBRICO | K10: MANUAL | L10: DG | M10: Con/Rest | Z10: Ocupada
A11: 9 | B11: 172.17.0.13 | C11: pendiente | Z11: Libre
A12: 10 | B12: 172.17.0.14 | C12: Arely Lira | D12: LAP | E12: Personal | F12: OTRO | J12: INALÁMBRICO | K12: MANUAL | L12: ST | Z12: Ocupada
A13: 11 | B13: 172.17.0.15 | C13: invitadodg | D13: LAP | E13: Personal | F13: OTRO | J13: INALÁMBRICO | K13: MANUAL | L13: DG | Z13: Ocupada
A14: 12 | B14: 172.17.0.16 | C14: ARODRIGUEZ | D14: PC | E14: Personal | J14: ALÁMBRICO | K14: DHCP | L14: DAJ | N14: Sí | O14: No | P14: NO | Q14: NO | R14: Sí | S14: Sí | T14: Sí | U14: Sí | V14: NO | W14: Sí | X14: No | Y14: NO | Z14: Ocupada
A15: 13 | B15: 172.17.0.17 | C15: Ma. Lourdes | D15: PC | E15: Institucional | F15: ASUS | G15: OPTIPLEX 7090 | H15: / | J15: ALÁMBRICO | K15: MANUAL | L15: DF | M15: Con/Rest | N15: No | O15: No | P15: No | Q15: NO | R15: No | S15: NO | T15: No | U15: Sí | V15: NO | W15: Sí | X15: NO | Y15: NO | Z15: Ocupada
A16: 14 | B16: 172.17.0.18 | C16: Karla Perez | D16: CEL | E16: Personal | J16: INALÁMBRICO | K16: MANUAL | L16: DG | Z16: Ocupada
D19: IP´s | E19: LIBRE | F19: OCUPADA | G19: CONFLICTO | H19: TOTAL | J19: IP´s | K19: Con restricciones | M19: Sin restricciones
E20: =COUNTIF($Z$3:$Z$16,DATOS!O2) -> 1 | F20: =COUNTIF($Z$3:$Z$16,DATOS!O3) -> 13 | G20: =COUNTIF($Z$3:$Z$16,DATOS!O4) -> 0 | H20: =SUM(E20:G20) -> 14 | K20: =COUNTIF(M3:$M$16,DATOS!Q2) -> 6 | M20: =COUNTIF($M3:AA$16,DATOS!Q3) -> 2
D22: CONEXIONES | E22: =DATOS!G2 -> INALÁMBRICO | F22: =DATOS!G3 -> ALÁMBRICO | G22: =DATOS!G4 -> ALÁMBRICO/INALÁMBRICO | J22: REGRESAR A LA PESTALLA PRINCIPAL
E23: =COUNTIF(J3:$J$16,DATOS!G2) -> 8 | F23: =COUNTIF($J3:$J$16,DATOS!G3) -> 4 | G23: =COUNTIF($J3:$J$16,DATOS!G4) -> 0
D25: EQUIPOS | E25: PERSONALES | G25: INSTITUCIONALES

Sheet DBEJ
A1: =RANGO!E5 -> DIRECCIÓN DE BIENESTAR Y ESTIMULOS A LA JUVENTUD
A2: No. | B2: IP | C2: Usuario o nombre del propietario | D2: Tipo de equipo | E2: Institucional o Personal | F2: Marca | G2: modelo | H2: Número de Serie | I2: MAC | J2: Tipo de Conexión | K2: Confguración de red | L2: Área | M2: Restricciones | N2: YOUTUBE | O2: VIMEO | P2: SPOTIFY | Q2: OTRO STREAMING | R2: FACEBOOK | S2: TIK TOK | T2: INSTAGRAM | U2: WHATSAPP WEB | V2: OTRA RED SOCIAL | W2: SITIOS GUBERNAMENTALES | X2: NOTICIAS | Y2: OTRO | Z2: Estatus | AA2: OBSERVACIONES
A3: 1 | B3: 172.17.0.19 | C3: Miguel Vigilancia | D3: CEL | E3: Personal | F3: OPPO | Z3: Libre
A4: 2 | B4: 172.17.0.20 | C4: natalia ss | D4: CEL | E4: Personal | F4: APPLE | Z4: Libre
A5: 3 | B5: 172.17.0.21 | C5: Ivan Alejandro | D5: CEL | E5: Personal | F5: OPPO | Z5: Libre
A6: 4 | B6: 172.17.0.22 | C6: Jose Luis Morales | D6: CEL | E6: Personal | F6: OPPO | Z6: Libre
A7: 5 | B7: 172.17.0.23 | C7: Vigilancia | D7: CEL | E7: Personal | F7: XIAOMI | Z7: Libre
A8: 6 | B8: 172.17.0.24 | C8: NORMA TORRES | D8: LAP | E8: Personal | Z8: Libre | AA8: CS
A9: 7 | B9: 172.17.0.25 | C9: Xavier Romero | D9: LAP | E9: Personal | F9: HP | J9: INALÁMBRICO | K9: MANUAL | L9: DBEJ | Z9: Ocupada
A10: 8 | B10: 172.17.0.26 | C10: Servicio Social | D10: TABLET | E10: Personal | F10: APPLE | J10: INALÁMBRICO | K10: MANUAL | L10: DBEJ | Z10: Ocupada
A11: 9 | B11: 172.17.0.27 | C11: Victor Hugo Escobar | D11: LAP | E11: Personal | F11: DELL | Z11: Libre
A12: 10 | B12: 172.17.0.28 | C12: Maria_CERRANO | D12: LAP | E12: Institucional | F12: DELL | G12: latitude3420 | Z12: Ocupada | AA12: Finanzas
A13: 11 | B13: 172.17.0.29 | C13: Silvia Rodriguez | D13: LAP | E13: Institucional | F13: DELL | G13: latitude3420 | J13: INALÁMBRICO | K13: MANUAL | L13: DBEJ | M13: Con/Rest | Z13: Ocupada
A14: 12 | B14: 172.17.0.30 | C14: Daniela Arenas | D14: LAP | E14: Institucional | F14: DELL | G14: latitude3420 | H14: / | I14: 94-E2-3C-26-45-03 | J14: INALÁMBRICO | K14: MANUAL | L14: DBEJ | M14: Sin/Rest | Z14: Ocupada | AA14: Sequidad Finanzas
A15: 13 | B15: 172.17.0.31 | Z15: Libre
A16: 14 | B16: 172.17.0.32 | C16: Servicio Social | D16: TABLET | E16: Personal | J16: INALÁMBRICO | K16: MANUAL | L16: DBEJ | Z16: Ocupada
A17: 15 | B17: 172.17.0.33 | Z17: Libre
A18: 16 | B18: 172.17.0.34 | C18: ELAP-SEQUIDAD4 | D18: LAP | E18: Institucional | F18: DELL | G18: latitude3420 | H18: / | I18: 94-E2-3C-26-80-40 | J18: INALÁMBRICO | K18: MANUAL | L18: DBEJ | M18: Con/Rest | Z18: Ocupada | AA18: Finanzas
A19: 17 | B19: 172.17.0.35 | C19: Emiliano Pérez | D19: LAP | E19: Personal | F19: ASUS | G19: VivoBook | J19: INALÁMBRICO | K19: MANUAL | L19: DBEJ | M19: Con/Rest | Z19: Ocupada | AA19: Investigación
A20: 18 | B20: 172.17.0.36 | C20: ELAP-SEQUIDAD1 | D20: LAP | E20: Institucional | F20: DELL | G20: latitude3420 | H20: / | I20: 94-E2-3C-05-04-6A | J20: INALÁMBRICO | K20: MANUAL | L20: DBEJ | M20: Sin/Rest | Z20: Ocupada | AA20: Finanzas
A21: 19 | B21: 172.17.0.37 | C21: mjuan | D21: LAP | E21: Institucional | F21: DELL | G21: latitude3420 | H21: 8SLGW93 | I21: 94-E2-3C-26-44-E0 | J21: INALÁMBRICO | K21: MANUAL | L21: DBEJ | M21: Con/Rest | Z21: Ocupada
A22: 20 | B22: 172.17.0.38 | C22: mgarcia | D22: TABLET | E22: Personal | F22: SAMSUNG | G22: / | H22: R9PT103XNFN | I22: 48:61:ee:17:07:61 | J22: INALÁMBRICO | K22: MANUAL | L22: DBEJ | M22: Con/Rest | Z22: Ocupada
A23: 21 | B23: 172.17.0.39 | C23: nmosco | D23: LAP | E23: Institucional | F23: DELL | G23: latitude3420 | H23: / | I23: EC-63-D7-CF-B0-61 | J23: INALÁMBRICO | L23: DIEJ | M23: Con/Rest | N23: Sí | O23: No | P23: No | Q23: no | R23: No | S23: No | T23: No | U23: Sí | V23: no | W23: Sí | X23: No | Z23: Ocupada | AA23: Recursos Humanos
A24: 22 | B24: 172.17.0.40 | C24: Juan | D24: LAP | E24: Institucional | F24: DELL | G24: latitude3420 | H24: / | I24: 94-E2-3C-01-B9-DB | J24: INALÁMBRICO | K24: MANUAL | L24: DBEJ | M24: Con/Rest | Z24: Ocupada
A25: 23 | B25: 172.17.0.41 | Z25: Libre
A26: 24 | B26: 172.17.0.42 | C26: ARTURO ISRAEL GARCIA LUNA | D26: LAP | E26: Institucional | F26: DELL | G26: latitude3420 | H26: / | J26: INALÁMBRICO | K26: MANUAL | L26: DBEJ | M26: Con/Rest | Z26: Libre
A27: 25 | B27: 172.17.0.43 | Z27: Ocupada | AA27: Finanzas
A28: 26 | B28: 172.17.0.44 | C28: Jesús | D28: LAP | E28: Institucional | F28: DELL | G28: latitude3420 | H28: FRNGW93 | I28: 94:E2:3C:02:3C:DF | J28: INALÁMBRICO | K28: MANUAL | L28: DBEJ | M28: Con/Rest | Z28: Ocupada
A29: 27 | B29: 172.17.0.45 | C29: José Saucedo (s.s) | D29: LAP | E29: Institucional | Z29: Libre
A30: 28 | B30: 172.17.0.46 | C30: ELAP-TJOVEN2 | D30: LAP | E30: Institucional | F30: DELL | G30: latitude3420 | H30: / | I30: 94-E2-3C-01-DF-60 | J30: INALÁMBRICO | K30: MANUAL | L30: DBEJ | M30: Con/Rest | Z30: Ocupada
A31: 29 | B31: 172.17.0.47 | C31: Cristian Flores León | D31: LAP | E31: Personal | F31: LENOVO | Z31: Libre
A32: 30 | B32: 172.17.0.48 | Z32: Libre
A33: 31 | B33: 172.17.0.49 | C33: Hector Ernesto | D33: LAP | E33: Institucional | F33: DELL | G33: latitude3420 | Z33: Libre
A34: 32 | B34: 172.17.0.50 | Z34: Libre
A35: 33 | B35: 172.17.0.51 | C35: gabriela gaviño | D35: LAP | E35: Institucional | F35: DELL | G35: latitude3420 | Z35: Ocupada | AA35: Finanzas
A36: 34 | B36: 172.17.0.52 | C36: mgarcía | D36: PC | E36: Institucional | F36: DELL | G36: OPTIPLEX | J36: ALÁMBRICO | K36: MANUAL | Z36: Ocupada | AA36: Secretaría técnica
A37: 35 | B37: 172.17.0.53 | C37: elap-nponce (Saul Climaco) | D37: LAP | E37: Institucional | F37: DELL | G37: latitude3420 | H37: / | I37: 94:E2:3C:01:BA:49 | J37: INALÁMBRICO | K37: MANUAL | L37: DIEJ | M37: Con/Rest | Z37: Libre
A38: 36 | B38: 172.17.0.54 | C38: José Luis Morales Rivera | D38: LAP | E38: Institucional | F38: DELL | J38: INALÁMBRICO | K38: MANUAL | L38: DBEJ | Z38: Ocupada | AA38: Morgue
A39: 37 | B39: 172.17.0.55 | C39: Nueva Arely | D39: LAP | E39: Personal | F39: APPLE | Z39: Libre
A40: 38 | B40: 172.17.0.56 | C40: Isaac | D40: CEL | E40: Personal | F40: APPLE | Z40: Libre
...

Sheet DIEJ
A1: =RANGO!E6 -> DIRECCIÓN DE INESTIGACIÓN Y ESTUDIOS SOBRE JUVENTUDES
A2: No. | B2: IP | C2: Usuario o nombre del propietario | D2: Tipo de equipo | E2: Institucional o Personal | F2: Marca | G2: modelo | H2: Número de Serie | I2: MAC | J2: Tipo de Conexión | K2: Confguración de red | L2: Área | M2: Restricciones | N2: YOUTUBE | O2: VIMEO | P2: SPOTIFY | Q2: OTRO STREAMING | R2: FACEBOOK | S2: TIK TOK | T2: INSTAGRAM | U2: WHATSAPP WEB | V2: OTRA RED SOCIAL | W2: SITIOS GUBERNAMENTALES | X2: NOTICIAS | Y2: OTRO | Z2: Estatus | AA2: OBSERVACIONES
A3: 1 | B3: 172.17.0.100 | C3: Axel | D3: LAP | E3: Institucional | F3: DELL | G3: latitude | Z3: Ocupada
A4: 2 | B4: 172.17.0.101 | Z4: Libre
A5: 3 | B5: 172.17.0.102 | Z5: Libre
A6: 4 | B6: 172.17.0.103 | C6: zgarcia | D6: LAP | E6: Personal | L6: DIEJ | M6: Con/Rest | N6: Sí | O6: No | P6: No | Q6: no | R6: Sí | S6: Sí | T6: Sí | U6: Sí | V6: no | W6: Sí | X6: Sí | Y6: no | Z6: Ocupada
A7: 5 | B7: 172.17.0.104 | Z7: Libre
A8: 6 | B8: 172.17.0.105 | C8: cambio | D8: PC | E8: Institucional | F8: DELL | G8: OPTIPLEX 3080 | K8: MANUAL | L8: DF | N8: Sí | O8: No | P8: Sí | Q8: No | R8: No | S8: No | T8: No | U8: Sí | V8: No | W8: Sí | X8: Sí | Y8: Zoom | Z8: Ocupada | AA8: finanzas
A9: 7 | B9: 172.17.0.106 | C9: Joaquin Adres Chavira | Z9: Libre
A10: 8 | B10: 172.17.0.107 | C10: lrangel | D10: PC | E10: Institucional | F10: DELL | G10: OPTIPLEX 3080 | L10: DIEJ | M10: Con/Rest | N10: No | O10: No | P10: No | Q10: no | R10: No | S10: no | T10: No | U10: Sí | V10: no | W10: Sí | X10: No | Y10: no | Z10: Ocupada
A11: 9 | B11: 172.17.0.108 | Z11: Libre
A12: 10 | B12: 172.17.0.109 | C12: fausto martinez SS | D12: LAP | E12: Personal | L12: DIEJ | M12: Con/Rest | N12: Sí | O12: No | P12: No | Q12: no | R12: Sí | S12: No | T12: Sí | U12: Sí | V12: no | W12: Sí | X12: Sí | Y12: no | Z12: Ocupada
A13: 11 | B13: 172.17.0.110 | C13: Servicio Social Karla | D13: LAP | E13: Personal | F13: HP | G13: elitebook 840 GS | H13: 00330-51813-83560-AAOEM | J13: INALÁMBRICO | K13: MANUAL | L13: DIEJ | M13: Sin/Rest | Z13: Ocupada | AA13: Servicio Social Karla
A14: 12 | B14: 172.17.0.111 | C14: Citlali Carolina SS | D14: LAP | E14: Personal | F14: DELL | Z14: Libre
A15: 13 | B15: 172.17.0.112 | C15: jcontreras | D15: LAP | E15: Institucional | F15: DELL | G15: latitude | L15: DIEJ | M15: Con/Rest | N15: No | O15: no | P15: No | Q15: no | R15: No | S15: No | T15: No | U15: Sí | V15: no | W15: Sí | X15: Sí | Y15: no | Z15: Ocupada
A16: 14 | B16: 172.17.0.113 | C16: emiliano perez SS | D16: LAP | E16: Personal | L16: DIEJ | M16: Con/Rest | N16: Sí | O16: No | P16: No | Q16: NO | R16: No | S16: No | T16: No | U16: Sí | V16: NO | W16: Sí | X16: Sí | Y16: NO | Z16: Ocupada
A17: 15 | B17: 172.17.0.114 | C17: Servicio Social Pamela Guerrero (Arely) | D17: CEL | E17: Personal | F17: APPLE | G17: iphone 15 | H17: HL02FMH2JY | J17: INALÁMBRICO | K17: MANUAL | L17: DIEJ | M17: Con/Rest | Z17: Libre
A18: 16 | B18: 172.17.0.115 | D18: CEL | Z18: Libre
A19: 17 | B19: 172.17.0.116 | C19: Uriel Jarquin | D19: LAP | E19: Personal | F19: APPLE | G19: Macbook | Z19: Libre
A20: 18 | B20: 172.17.0.117 | Z20: Libre
A21: 19 | B21: 172.17.0.118 | C21: Callcenter | Z21: Libre
A22: 20 | B22: 172.17.0.119 | Z22: Libre
A23: 21 | B23: 172.17.0.120 | C23: Posiblemente el Servidor del dns | Z23: Libre
A24: 22 | B24: 172.17.0.121 | Z24: Libre
A25: 23 | B25: 172.17.0.122 | C25: Axel | Z25: Libre
A26: 24 | B26: 172.17.0.123 | Z26: Libre
A27: 25 | B27: 172.17.0.124 | Z27: Libre
A28: 26 | B28: 172.17.0.125 | Z28: Libre
A29: 27 | B29: 172.17.0.126 | C29: ANA PATRICIA/ IPAD/CEL SS | D29: TABLET | L29: DRHM | Z29: Libre
A30: 28 | B30: 172.17.0.127 | C30: AARON SS | D30: CEL | E30: Personal | L30: DRHM | Z30: Libre
A31: 29 | B31: 172.17.0.128 | C31: Uriel Jarquin | D31: CEL | E31: Personal | Z31: Libre
A32: 30 | B32: 172.17.0.129 | C32: Uriel Macbook air | D32: LAP | E32: Personal | F32: APPLE | G32: Macbook | Z32: Libre
A33: 31 | B33: 172.17.0.130 | Z33: Libre
A34: 32 | B34: 172.17.0.131 | C34: Eduardo Vargas | D34: LAP | E34: Personal | F34: HP | Z34: Libre
A35: 33 | B35: 172.17.0.132 | C35: Juan de Dios Garcia | D35: LAP | E35: Personal | F35: LENOVO | Z35: Ocupada | AA35: CS
A36: 34 | B36: 172.17.0.133 | Z36: Libre
A37: 35 | B37: 172.17.0.134 | Z37: Ocupada
A38: 36 | B38: 172.17.0.135 | Z38: Libre
A39: 37 | B39: 172.17.0.136 | C39: Karla Olvera Alvarado | D39: LAP | E39: Personal | F39: HP | Z39: Ocupada
A40: 38 | B40: 172.17.0.137 | Z40: Libre
...

Sheet DCSR
A1: =RANGO!E7 -> DIRECCIÓN DE COORDINACIÓN SERCTORIAL Y REGIONAL
A2: No. | B2: IP | C2: Usuario o nombre del propietario | D2: Tipo de equipo | E2: Institucional o Personal | F2: Marca | G2: modelo | H2: Número de Serie | I2: MAC | J2: Tipo de Conexión | K2: Confguración de red | L2: Área | M2: Restricciones | N2: YOUTUBE | O2: VIMEO | P2: SPOTIFY | Q2: OTRO STREAMING | R2: FACEBOOK | S2: TIK TOK | T2: INSTAGRAM | U2: WHATSAPP WEB | V2: OTRA RED SOCIAL | W2: SITIOS GUBERNAMENTALES | X2: NOTICIAS | Y2: OTRO | Z2: Estatus | AA2: OBSERVACIONES
A3: 1 | B3: 172.17.0.158 | C3: agalindo | D3: LAP | E3: Institucional | F3: DELL | G3: latitude3420 | H3: 4RLGW93 | I3: 94:E2:3C:25:62:6E | J3: INALÁMBRICO | K3: MANUAL | L3: DCSR | M3: Con/Rest | N3: Sí | O3: Sí | P3: Sí | Q3: no | R3: Sí | S3: Sí | T3: Sí | U3: Sí | V3: no | W3: Sí | X3: Sí | Y3: no | Z3: Ocupada
A4: 2 | B4: 172.17.0.159 | C4: omar sumaya | D4: LAP | E4: Institucional | F4: DELL | G4: latitude3420 | K4: MANUAL | L4: DCSR | M4: Con/Rest | Z4: Ocupada
A5: 3 | B5: 172.17.0.160 | Z5: Libre
A6: 4 | B6: 172.17.0.161 | C6: cgalindo | D6: LAP | E6: Institucional | F6: DELL | G6: latitude3420 | H6: / | I6: 14-85-7F-FF-CB-D4 | J6: INALÁMBRICO | K6: MANUAL | L6: DCSR | M6: Sin/Rest | N6: Sí | O6: Sí | P6: Sí | Q6: no | R6: Sí | S6: Sí | T6: Sí | U6: Sí | V6: no | W6: Sí | X6: Sí | Y6: no | Z6: Ocupada
A7: 5 | B7: 172.17.0.162 | C7: Yoceline Tablet | D7: TABLET | E7: Personal | F7: HUAWEI | Z7: Libre
A8: 6 | B8: 172.17.0.163 | C8: ELAP-LYESCA | D8: LAP | E8: Institucional | F8: DELL | G8: latitude3420 | H8: / | I8: 94-E2-3C-00-CC-7E | J8: INALÁMBRICO | K8: MANUAL | L8: DCSR | M8: Con/Rest | N8: No | O8: No | P8: no | Q8: no | R8: No | S8: No | T8: No | U8: Sí | V8: no | W8: Sí | X8: No | Y8: no | Z8: Ocupada
A9: 7 | B9: 172.17.0.164 | C9: Patricia | D9: LAP | E9: Personal | F9: DELL | L9: DCSR | M9: Con/Rest | N9: Sí | O9: No | P9: no | Q9: no | R9: Sí | S9: Sí | T9: Sí | U9: Sí | V9: no | W9: Sí | X9: Sí | Y9: no | Z9: Ocupada
A10: 8 | B10: 172.17.0.165 | C10: Federico Vidal | D10: LAP | E10: Personal | F10: LENOVO | L10: DCSR | M10: Con/Rest | N10: Sí | O10: No | P10: Sí | Q10: no | R10: Sí | S10: No | T10: Sí | U10: Sí | V10: no | W10: Sí | X10: Sí | Y10: no | Z10: Ocupada
A11: 9 | B11: 172.17.0.166 | C11: sofia acevedo | D11: LAP | E11: Institucional | F11: DELL | Z11: Libre
A12: 10 | B12: 172.17.0.167 | C12: Diego silis | D12: LAP | E12: Personal | L12: DCSR | M12: Con/Rest | N12: Sí | O12: No | P12: no | Q12: no | R12: Sí | S12: Sí | T12: Sí | U12: Sí | V12: no | W12: Sí | X12: Sí | Y12: no | Z12: Ocupada
A13: 11 | B13: 172.17.0.168 | C13: ELAP-GTORRES | D13: LAP | E13: Institucional | F13: DELL | G13: latitude3420 | H13: / | I13: 94-E2-3C-00-41-3C | J13: INALÁMBRICO | K13: MANUAL | L13: OIC | M13: Con/Rest | Z13: Ocupada
A14: 12 | B14: 172.17.0.169 | C14: emiliano | D14: LAP | E14: Personal | G14: desktop-1qlsljr | Z14: Libre
A15: 13 | B15: 172.17.0.170 | C15: Karen Ramírez (Servicio Social) | D15: LAP | E15: Personal | F15: LENOVO | J15: INALÁMBRICO | K15: MANUAL | L15: DCSR | Z15: Ocupada | AA15: Servicio Social
A16: 14 | B16: 172.17.0.171 | C16: psandoval / Invitado | D16: PC | E16: Institucional | F16: DELL | G16: OPTIPLEX 3080 | H16: 8D5YDF3 | I16: B0-4F-13-01-AF-AF | J16: ALÁMBRICO | K16: MANUAL | L16: DCSR | M16: Con/Rest | Z16: Ocupada
A17: 15 | B17: 172.17.0.172 | C17: hmartinez | D17: PC | E17: Institucional | F17: DELL | G17: OPTIPLEX 3080 | H17: 8MMWDF3 | I17: B0-4F-13-00-FA-81 | J17: ALÁMBRICO | K17: MANUAL | L17: DCSR | M17: Con/Rest | N17: Sí | O17: Sí | P17: No | Q17: no | R17: Sí | S17: Sí | T17: Sí | U17: Sí | V17: no | W17: Sí | X17: Sí | Y17: no | Z17: Ocupada
A18: 16 | B18: 172.17.0.173 | C18: bulloa | D18: LAP | E18: Institucional | F18: DELL | L18: DCSR | M18: Con/Rest | Z18: Libre
A19: 17 | B19: 172.17.0.174 | Z19: Libre
A20: 18 | B20: 172.17.0.175 | C20: Edith G. Pérez | D20: LAP | E20: Institucional | F20: DELL | Z20: Ocupada
A21: 19 | B21: 172.17.0.176 | Z21: Libre
A22: 20 | B22: 172.17.0.177 | Z22: Libre
A23: 21 | B23: 172.17.0.178 | Z23: Libre
A24: 22 | B24: 172.17.0.179 | C24: Eduardo Hernandez | D24: LAP | E24: Personal | F24: HP | Z24: Libre
A25: 23 | B25: 172.17.0.180 | Z25: Libre
A26: 24 | B26: 172.17.0.181 | Z26: Libre
A27: 25 | B27: 172.17.0.182 | Z27: Libre
A28: 26 | B28: 172.17.0.183 | C28: Areli DG | Z28: Libre
A29: 27 | B29: 172.17.0.184 | Z29: Libre
A30: 28 | B30: 172.17.0.185 | Z30: Libre
A31: 29 | B31: 172.17.0.186 | C31: Fernando Quiñales Servicio Social | Z31: Ocupada
A32: 30 | B32: 172.17.0.187 | C32: Kevin Gabriel | D32: LAP | E32: Personal | F32: APPLE | Z32: Libre
A33: 31 | B33: 172.17.0.188 | Z33: Libre
A34: 32 | B34: 172.17.0.189 | Z34: Libre
A35: 33 | B35: 172.17.0.190 | C35: Evelyn SS | D35: LAP | E35: Institucional | F35: DELL | Z35: Libre
A36: 34 | B36: 172.17.0.191 | Z36: Libre
A37: 35 | B37: 172.17.0.192 | C37: Sofia Garcia Servicio Social | D37: TABLET | E37: Personal | F37: APPLE | Z37: Libre
A38: 36 | B38: 172.17.0.193 | Z38: Libre
A39: 37 | B39: 172.17.0.194 | Z39: Libre
A40: 38 | B40: 172.17.0.195 | Z40: Libre
...

Sheet DAJ
A1: =RANGO!E11 -> DIRECCIÓN DE ASUSTOS JURÍDICOS
A2: No. | B2: IP | C2: Usuario o nombre del propietario | D2: Tipo de equipo | E2: Institucional o Personal | F2: Marca | G2: modelo | H2: Número de Serie | I2: MAC | J2: Tipo de Conexión | K2: Confguración de red | L2: Área | M2: Restricciones | N2: YOUTUBE | O2: VIMEO | P2: SPOTIFY | Q2: OTRO STREAMING | R2: FACEBOOK | S2: TIK TOK | T2: INSTAGRAM | U2: WHATSAPP WEB | V2: OTRA RED SOCIAL | W2: SITIOS GUBERNAMENTALES | X2: NOTICIAS | Y2: OTRO | Z2: Estatus | AA2: OBSERVACIONES
A3: 1 | B3: 172.17.1.85 | C3: Yocelin | D3: LAP | E3: Institucional | F3: DELL | G3: latitude3420 | H3: D9KGW93 | I3: 14:85:7F:FF:D8:90 | J3: INALÁMBRICO | K3: MANUAL | L3: DCSR | M3: Con/Rest | N3: Sí | O3: Sí | P3: Sí | Q3: no | R3: Sí | S3: Sí | T3: Sí | U3: Sí | V3: no | W3: Sí | X3: Sí | Y3: no | Z3: Ocupada
A4: 2 | B4: 172.17.1.86 | Z4: Libre
A5: 3 | B5: 172.17.1.87 | Z5: Ocupada | AA5: Coordinación sectorial
A6: 4 | B6: 172.17.1.88 | Z6: Libre
A7: 5 | B7: 172.17.1.89 | C7: arodriguez | D7: PC | E7: Institucional | F7: DELL | G7: OPTIPLEX 7090 | H7: 8D82FF3 | I7: / | J7: ALÁMBRICO | K7: MANUAL | L7: DAJ | M7: Con/Rest | Z7: Ocupada
A8: 6 | B8: 172.17.1.90 | C8: EPC-ECAMARGO | D8: PC | E8: Institucional | F8: DELL | G8: OPTIPLEX 3080 | H8: / | I8: B0-4F-13-01-AA-2A | J8: ALÁMBRICO | K8: MANUAL | L8: DAJ | M8: Con/Rest | N8: No | O8: NO | P8: No | Q8: NO | R8: No | S8: NO | T8: No | U8: Sí | V8: NO | W8: Sí | X8: No | Y8: NO | Z8: Ocupada
A9: 7 | B9: 172.17.1.91 | Z9: Libre
A10: 8 | B10: 172.17.1.92 | C10: AMartinez | D10: pc | E10: Institucional | F10: DELL | G10: OPTIPLEX 3080 | Z10: Libre
A11: 9 | B11: 172.17.1.93 | M11: Sin/Rest | N11: Sí | O11: No | P11: NO | Q11: NO | R11: No | S11: No | T11: NO | U11: Sí | V11: NO | W11: Sí | X11: NO | Y11: NO | Z11: Ocupada | AA11: RH
A12: 10 | B12: 172.17.1.94 | Z12: Libre
A13: 11 | B13: 172.17.1.95 | Z13: Libre
A14: 12 | B14: 172.17.1.96 | Z14: Libre
A15: 13 | B15: 172.17.1.97 | C15: MARCELA HUERTA | D15: PC | E15: Institucional | F15: DELL | L15: DAJ | M15: Con/Rest | N15: Sí | O15: No | P15: No | Q15: NO | R15: Sí | S15: Sí | T15: Sí | U15: Sí | V15: NO | W15: Sí | X15: No | Y15: NO | Z15: Ocupada
A16: 14 | B16: 172.17.1.98 | Z16: Libre
A17: 15 | B17: 172.17.1.99 | Z17: Libre
A18: 16 | B18: 172.17.1.100 | C18: Lsanchez | D18: lap | E18: Personal | F18: APPLE | G18: MACBOOKAIR-568D | H18: / | I18: 2A-F2-AD-45-88-82 | J18: INALÁMBRICO | K18: MANUAL | L18: DAJ | M18: Con/Rest | N18: No | O18: NO | P18: No | Q18: NO | R18: No | S18: NO | T18: No | U18: Sí | V18: NO | W18: Sí | X18: No | Y18: NO | Z18: Ocupada
A19: 17 | B19: 172.17.1.101 | Z19: Libre
A20: 18 | B20: 172.17.1.102 | Z20: Libre
A21: 19 | B21: 172.17.1.103 | Z21: Libre
D23: IP´s | E23: LIBRE | F23: OCUPADA | G23: CONFLICTO | H23: TOTAL | J23: IP´s | K23: Con restricciones | M23: Sin restricciones
E24: =COUNTIF($Z$3:$Z$21,DATOS!O2) -> 12 | F24: =COUNTIF($Z$3:$Z$21,DATOS!O3) -> 7 | G24: =COUNTIF($Z$3:$Z$21,DATOS!O4) -> 0 | H24: =SUM(E24:G24) -> 19 | K24: =COUNTIF(M3:$M$21,DATOS!Q2) -> 5 | M24: =COUNTIF($M3:$M$21,DATOS!Q3) -> 1
D26: CONEXIONES | E26: =DATOS!G2 -> INALÁMBRICO | F26: =DATOS!G3 -> ALÁMBRICO | G26: =DATOS!G4 -> ALÁMBRICO/INALÁMBRICO | J26: REGRESAR A LA PESTALLA PRINCIPAL
E27: =COUNTIF(J3:$J$21,DATOS!G2) -> 2 | F27: =COUNTIF(J3:J21,DATOS!G3) -> 2 | G27: =COUNTIF($J3:$J$21,DATOS!G4) -> 0

Sheet DEC
A1: =RANGO!E8 -> DIRECCIÓN DE EVALUACIÓN Y CONTROL
A2: No. | B2: IP | C2: Usuario o nombre del propietario | D2: Tipo de equipo | E2: Institucional o Personal | F2: Marca | G2: modelo | H2: Número de Serie | I2: MAC | J2: Tipo de Conexión | K2: Confguración de red | L2: Área | M2: Restricciones | N2: YOUTUBE | O2: VIMEO | P2: SPOTIFY | Q2: OTRO STREAMING | R2: FACEBOOK | S2: TIK TOK | T2: INSTAGRAM | U2: WHATSAPP WEB | V2: OTRA RED SOCIAL | W2: SITIOS GUBERNAMENTALES | X2: NOTICIAS | Y2: OTRO | Z2: Estatus | AA2: OBSERVACIONES
A3: 1 | B3: 172.17.0.206 | Z3: Libre
A4: 2 | B4: 172.17.0.207 | Z4: Libre
A5: 3 | B5: 172.17.0.208 | C5: call | Z5: Libre
A6: 4 | B6: 172.17.0.209 | C6: call | Z6: Libre
A7: 5 | B7: 172.17.0.210 | C7: Uriel jarquin | D7: LAP | E7: Institucional | F7: DELL | Z7: Libre
A8: 6 | B8: 172.17.0.211 | C8: elap-dluna | D8: LAP | E8: Institucional | F8: DELL | G8: latitude3420 | I8: 14:85:7F:FF:F0:19 | Z8: Ocupada
A9: 7 | B9: 172.17.0.212 | C9: azoquiapa | D9: PC | E9: Institucional | F9: DELL | G9: OPTIPLEX 3080 | H9: / | I9: B0-4F-13-01-B2-27 | J9: ALÁMBRICO | K9: MANUAL | L9: DEC | M9: Con/Rest | Z9: Ocupada
A10: 8 | B10: 172.17.0.213 | Z10: Libre
A11: 9 | B11: 172.17.0.214 | Z11: Libre
A12: 10 | B12: 172.17.0.215 | C12: ELAP-LRODRIGUEZ | D12: LAP | E12: Institucional | F12: DELL | G12: latitude3420 | J12: INALÁMBRICO | K12: MANUAL | L12: DEC | M12: Con/Rest | Z12: Ocupada
A13: 11 | B13: 172.17.0.216 | C13: Piedad | D13: LAP | E13: Institucional | F13: DELL | Z13: Ocupada
A14: 12 | B14: 172.17.0.217 | C14: elap-kpena | D14: LAP | E14: Institucional | F14: DELL | G14: latitude3420 | H14: 3MLGW93 | I14: 14:85:7F:FF:10:F9 | J14: INALÁMBRICO | K14: MANUAL | L14: DEC | M14: Con/Rest | Z14: Ocupada
A15: 13 | B15: 172.17.0.218 | Z15: Libre
A16: 14 | B16: 172.17.0.219 | Z16: Libre
A17: 15 | B17: 172.17.0.220 | C17: Alejandra SS | D17: LAP | E17: Personal | F17: DELL | L17: DRHM | Z17: Ocupada
A18: 16 | B18: 172.17.0.221 | Z18: Libre
A19: 17 | B19: 172.17.0.222 | Z19: Libre
A20: 18 | B20: 172.17.0.223 | Z20: Libre
A21: 19 | B21: 172.17.0.224 | C21: Ricardo Cruz | D21: LAP | E21: Institucional | F21: DELL | J21: INALÁMBRICO | K21: MANUAL | L21: DEC | Z21: Ocupada
A22: 20 | B22: 172.17.0.225 | C22: Hazziel | D22: PC | E22: Personal | F22: APPLE | Z22: Ocupada
A23: 21 | B23: 172.17.0.226 | C23: Ana patricia | D23: CEL | E23: Personal | F23: APPLE | L23: DRHM | Z23: Ocupada | AA23: RH
A24: 22 | B24: 172.17.0.227 | C24: Hazziel | D24: LAP | E24: Institucional | F24: DELL | Z24: Ocupada
A25: 23 | B25: 172.17.0.228 | C25: call | D25: CEL | Z25: Libre
A26: 24 | B26: 172.17.0.229 | C26: call | D26: CEL | Z26: Libre
A27: 25 | B27: 172.17.0.230 | Z27: Libre
A28: 26 | B28: 172.17.0.231 | C28: call | D28: CEL | Z28: Libre
A29: 27 | B29: 172.17.0.232 | C29: Emiliano | D29: LAP | E29: Personal | F29: HUAWEI | Z29: Ocupada
A30: 28 | B30: 172.17.0.233 | C30: call | Z30: Libre
A31: 29 | B31: 172.17.0.234 | C31: call | Z31: Libre
A32: 30 | B32: 172.17.0.235 | Z32: Libre
A33: 31 | B33: 172.17.0.236 | Z33: Libre
A34: 32 | B34: 172.17.0.237 | Z34: Libre
A35: 33 | B35: 172.17.0.238 | Z35: Libre
A36: 34 | B36: 172.17.0.239 | C36: jsigales | D36: CEL | E36: Personal | F36: APPLE | Z36: Ocupada
A37: 35 | B37: 172.17.0.240 | C37: Romina SS | D37: LAP | E37: Personal | F37: HP | J37: INALÁMBRICO | K37: MANUAL | L37: DEC | Z37: Ocupada
A38: 36 | B38: 172.17.0.241 | Z38: Libre
A39: 37 | B39: 172.17.0.242 | Z39: Libre
D41: IP´s | E41: LIBRE | F41: OCUPADA | G41: CONFLICTO | H41: TOTAL | J41: IP´s | K41: Con restricciones | M41: Sin restricciones
...

Sheet DF
A1: =RANGO!E9 -> DIRECCIÓN DE FINANZAS
A2: No. | B2: IP | C2: Usuario o nombre del propietario | D2: Tipo de equipo | E2: Institucional o Personal | F2: Marca | G2: modelo | H2: Número de Serie | I2: MAC | J2: Tipo de Conexión | K2: Confguración de red | L2: Área | M2: Restricciones | N2: YOUTUBE | O2: VIMEO | P2: SPOTIFY | Q2: OTRO STREAMING | R2: FACEBOOK | S2: TIK TOK | T2: INSTAGRAM | U2: WHATSAPP WEB | V2: OTRA RED SOCIAL | W2: SITIOS GUBERNAMENTALES | X2: NOTICIAS | Y2: OTRO | Z2: Estatus | AA2: OBSERVACIONES
A3: 1 | B3: 172.17.0.243 | C3: Dulce sarmiento | D3: LAP | E3: Institucional | F3: DELL | G3: OPTIPLEX 3080 | H3: / | I3: 94:E2:3C:01:BA:49 | J3: INALÁMBRICO | K3: MANUAL | L3: DIEJ | M3: Con/Rest | N3: Sí | O3: No | P3: Sí | R3: no | S3: No | T3: No | U3: Sí | W3: Sí | X3: Sí | Y3: zoom | Z3: Ocupada
A4: 2 | B4: 172.17.0.244 | Z4: Libre
A5: 3 | B5: 172.17.0.245 | C5: MUVALLE/OMAR SAUD | D5: PC | E5: Institucional | L5: DF | M5: Con/Rest | N5: No | O5: No | P5: Sí | Q5: NO | R5: No | S5: No | T5: No | U5: Sí | V5: NO | W5: Sí | X5: Sí | Y5: ZOOM | Z5: Ocupada
A6: 4 | B6: 172.17.0.246 | C6: amedina | D6: pc | E6: Institucional | F6: DELL | L6: DF | M6: Con/Rest | N6: No | O6: no | P6: Sí | Q6: no | R6: no | S6: No | T6: no | U6: sí | V6: no | W6: Sí | X6: Sí | Y6: zoom | Z6: Ocupada
A7: 5 | B7: 172.17.0.247 | Z7: Libre
A8: 6 | B8: 172.17.0.248 | C8: glira | D8: LAP | E8: Institucional | F8: DELL | G8: latitude3420 | H8: 1TLGW93 | I8: 94-E2-3C-26-80-90 | J8: INALÁMBRICO | K8: MANUAL | L8: DBEJ | M8: Con/Rest | N8: No | O8: No | P8: Sí | Q8: NO | R8: No | S8: No | T8: No | U8: Sí | V8: NO | W8: Sí | X8: Sí | Y8: ZOOM | Z8: Ocupada
A9: 7 | B9: 172.17.0.249 | C9: sreyes | D9: LAP | E9: Institucional | F9: DELL | G9: latitude3420 | H9: 93KGW93 | J9: INALÁMBRICO | K9: MANUAL | L9: DF | M9: Con/Rest | N9: No | O9: No | P9: Sí | Q9: NO | R9: No | S9: No | T9: No | U9: Sí | V9: NO | W9: Sí | X9: Sí | Y9: NO | Z9: Ocupada
A10: 8 | B10: 172.17.0.250 | C10: JLopez | D10: CEL | E10: Personal | F10: XIAOMI | Z10: Libre
A11: 9 | B11: 172.17.0.251 | C11: ELAP-JALOPEZ | D11: LAP | E11: Institucional | F11: DELL | G11: latitude3420 | H11: CBJGW93 | J11: INALÁMBRICO | K11: MANUAL | L11: DF | M11: Con/Rest | N11: Sí | O11: No | P11: No | Q11: NO | R11: No | S11: No | T11: No | U11: Sí | V11: NO | W11: Sí | X11: Sí | Y11: ZOOM | Z11: Ocupada
A12: 10 | B12: 172.17.0.252 | C12: EPC-JALOPEZ1 | D12: PC | E12: Institucional | F12: DELL | G12: OPTIPLEX 7090 | H12: 9WND2G3 | I12: D0-8E-79-05-23-29 | J12: INALÁMBRICO | K12: MANUAL | L12: DF | M12: Con/Rest | N12: Sí | O12: No | P12: No | Q12: NO | R12: No | S12: No | T12: No | U12: Sí | V12: NO | W12: Sí | X12: Sí | Y12: ZOOM | Z12: Ocupada
A13: 11 | B13: 172.17.0.253 | C13: vcastro | D13: PC | E13: Institucional | F13: DELL | L13: DF | N13: Sí | O13: No | P13: Sí | Q13: NO | R13: No | S13: NO | T13: NO | U13: Sí | V13: NO | W13: Sí | X13: Sí | Y13: ZOOM | Z13: Ocupada
A14: 12 | B14: 172.17.0.254 | C14: mixtli peñaloza | D14: PC | E14: Institucional | F14: DELL | G14: OPTIPLEX 3080 | H14: 8ML0FF3 | I14: B0-4F-13-00-FA-AF | J14: ALÁMBRICO | K14: MANUAL | L14: DF | M14: Con/Rest | Z14: Ocupada
A15: 13 | B15: 172.17.1.01 | C15: DCARVENTE | D15: PC | E15: Institucional | F15: DELL | J15: INALÁMBRICO | K15: MANUAL | L15: DF | M15: Con/Rest | N15: Sí | O15: No | P15: Sí | Q15: NO | R15: NO | S15: NO | T15: No | U15: Sí | V15: NO | W15: Sí | X15: Sí | Y15: ZOOM, TEAMS | Z15: Ocupada
A16: 14 | B16: 172.17.1.02 | C16: JSANCHEZ | D16: PC | E16: Institucional | F16: DELL | G16: OPTIPLEX 7090 | L16: DF | M16: Con/Rest | N16: Sí | O16: No | P16: Sí | Q16: NO | R16: No | S16: No | T16: No | U16: Sí | V16: NO | W16: Sí | X16: Sí | Y16: ZOOM | Z16: Ocupada
A17: 15 | B17: 172.17.1.03 | C17: EPC-AGARCIAR | D17: PC | E17: Institucional | F17: DELL | G17: OPTIPLEX 7090 | H17: 9WMJ2G3 | I17: D0-8E-79-05-23-3B | J17: ALÁMBRICO | K17: MANUAL | L17: DF | M17: Con/Rest | N17: No | O17: No | P17: Sí | Q17: NO | R17: No | S17: No | T17: No | U17: Sí | V17: NO | W17: Sí | X17: Sí | Y17: ZOOM, TIDAL MUSIC | Z17: Ocupada
A18: 16 | B18: 172.17.1.04 | C18: avilla | D18: LAP | E18: Institucional | F18: DELL | G18: latitude3420 | H18: 2GJGW93 | I18: C0-25-A5-47-4F-77 | J18: INALÁMBRICO | K18: MANUAL | L18: DF | M18: Con/Rest | N18: No | O18: No | P18: Sí | Q18: NO | R18: No | S18: No | T18: No | U18: Sí | V18: NO | W18: Sí | X18: Sí | Y18: ZOOM | Z18: Ocupada
A19: 17 | B19: 172.17.1.05 | C19: Fernanda Mosso | D19: LAP | E19: Institucional | F19: DELL | J19: INALÁMBRICO | K19: MANUAL | L19: DF | Z19: Ocupada
A20: 18 | B20: 172.17.1.06 | Z20: Libre
A21: 19 | B21: 172.17.1.07 | C21: pmixtli | D21: CEL | E21: Personal | F21: SAMSUNG | L21: DF | M21: Con/Rest | N21: Sí | O21: No | P21: No | Q21: amazon music | R21: No | S21: No | T21: No | U21: Sí | V21: no | W21: Sí | X21: Sí | Y21: zoom, teams | Z21: Ocupada
A22: 20 | B22: 172.17.1.08 | Z22: Libre
A23: 21 | B23: 172.17.1.09 | C23: EPC-AAMADOR | D23: PC | E23: Institucional | F23: DELL | G23: OPTIPLEX 7090 | H23: / | I23: B0-4F-13-01-AA-5C | J23: ALÁMBRICO | K23: MANUAL | L23: DF | M23: Con/Rest | N23: No | O23: No | P23: Sí | Q23: NO | R23: No | S23: No | T23: No | U23: Sí | V23: NO | W23: Sí | X23: Sí | Y23: ZOOM | Z23: Ocupada
A24: 22 | B24: 172.17.1.10 | Z24: Libre
A25: 23 | B25: 172.17.1.11 | C25: DCARVENTE | Z25: Libre
A26: 24 | B26: 172.17.1.12 | Z26: Libre
A27: 25 | B27: 172.17.1.13 | C27: Laptop Finanzas | D27: LAP | E27: Personal | Z27: Libre
A28: 26 | B28: 172.17.1.14 | C28: omar saud | D28: PC | E28: Institucional | Z28: Libre
A29: 27 | B29: 172.17.1.15 | Z29: Libre
A30: 28 | B30: 172.17.1.16 | C30: MUVALLE | Z30: Libre
A31: 29 | B31: 172.17.1.17 | C31: ITZEL | D31: CEL | E31: Personal | F31: APPLE | N31: Sí | O31: Sí | P31: Sí | Q31: Sí | R31: Sí | S31: Sí | T31: Sí | U31: Sí | V31: Sí | W31: Sí | X31: Sí | Y31: Sí | Z31: Ocupada | AA31: RELACIONES INTERNACIONALES
A32: 30 | B32: 172.17.1.18 | Z32: Libre
A33: 31 | B33: 172.17.1.19 | Z33: Libre
A34: 32 | B34: 172.17.1.20 | C34: ITZEL | D34: LAP | E34: Institucional | F34: DELL | L34: DCS | M34: Con/Rest | N34: Sí | O34: Sí | P34: Sí | Q34: Sí | R34: Sí | S34: Sí | T34: Sí | U34: Sí | V34: Sí | W34: Sí | X34: Sí | Y34: Sí | Z34: Ocupada | AA34: RELACIONES INTERNACIONALES
A35: 33 | B35: 172.17.1.21 | C35: Tarjeta joven 1 | Z35: Ocupada
A36: 34 | B36: 172.17.1.22 | C36: WENDY | D36: CEL | E36: Personal | F36: APPLE | G36: IPHONE | N36: Sí | O36: Sí | P36: Sí | Q36: Sí | R36: Sí | S36: Sí | T36: Sí | U36: Sí | V36: Sí | W36: Sí | X36: Sí | Y36: Sí | Z36: Ocupada | AA36: RELACIONES INTERNACIONALES
D38: IP´s | E38: LIBRE | F38: OCUPADA | G38: CONFLICTO | H38: TOTAL | J38: IP´s | K38: Con restricciones | M38: Sin restricciones
E39: =COUNTIF($Z$3:$Z$36,DATOS!O2) -> 14 | F39: =COUNTIF($Z$3:$Z$36,DATOS!O3) -> 20 | G39: =COUNTIF($Z$3:$Z$36,DATOS!O4) -> 0 | H39: =SUM(E39:G39) -> 34 | K39: =COUNTIF(M3:$M$36,DATOS!Q2) -> 15 | M39: =COUNTIF($M3:$M$36,DATOS!Q3) -> 0
D41: CONEXIONES | E41: =DATOS!G2 -> INALÁMBRICO | F41: =DATOS!G3 -> ALÁMBRICO | G41: =DATOS!G4 -> ALÁMBRICO/INALÁMBRICO | J41: REGRESAR A LA PESTALLA PRINCIPAL
E42: =COUNTIF(J3:$J$36,DATOS!G2) -> 8 | F42: =COUNTIF(J3:J36,DATOS!G3) -> 3 | G42: =COUNTIF($J3:$J$36,DATOS!G4) -> 0

Sheet DRHM
A1: =RANGO!E10 -> DIRECCIÓN DE RECURSOS HUMANOS Y MATERIALES
A2: No. | B2: IP | C2: Usuario o nombre del propietario | D2: Tipo de equipo | E2: Institucional o Personal | F2: Marca | G2: modelo | H2: Número de Serie | I2: MAC | J2: Tipo de Conexión | K2: Confguración de red | L2: Área | M2: Restricciones | N2: YOUTUBE | O2: VIMEO | P2: SPOTIFY | Q2: OTRO STREAMING | R2: FACEBOOK | S2: TIK TOK | T2: INSTAGRAM | U2: WHATSAPP WEB | V2: OTRA RED SOCIAL | W2: SITIOS GUBERNAMENTALES | X2: NOTICIAS | Y2: OTRO | Z2: Estatus | AA2: OBSERVACIONES
A3: 1 | B3: 172.17.1.23 | C3: Seguridad Giller,o Callejas | D3: CEL | E3: personal | F3: SAMSUNG | G3: sm-a037m | H3: r9hrb02cjtk | J3: INALÁMBRICO | K3: MANUAL | Z3: Conflicto | AA3: Muy lenta , seguridad
A4: 2 | B4: 172.17.1.24 | C4: CROMERO | D4: PC | E4: INSTITUCIONAL | L4: DRHM | N4: NO | O4: NO | P4: NO | Q4: NO | R4: NO | S4: NO | T4: NO | U4: SÍ | V4: NO | W4: SÍ | X4: NO | Y4: NO | Z4: Ocupada
A5: 3 | B5: 172.17.1.25 | D5: pc | E5: INSTITUCIONAL | Z5: Libre
A6: 4 | B6: 172.17.1.26 | C6: msandoval | D6: LAP | E6: Personal | F6: DELL | G6: OPTIPLEX 3080 | H6: / | I6: D0:8E79:05:23:37 | J6: INALÁMBRICO | K6: MANUAL | L6: DRHM | M6: Con/Rest | Z6: Ocupada
A7: 5 | B7: 172.17.1.27 | C7: Subdirección RHM | D7: LAP | E7: Institucional | F7: DELL | G7: latitude3420 | H7: / | I7: EC-63-D7-CF-04-EA | J7: INALÁMBRICO | K7: MANUAL | L7: DRHM | M7: Con/Rest | Z7: Ocupada | AA7: Finanzas
A8: 6 | B8: 172.17.1.28 | C8: aron lap ss psi | D8: LAP | E8: Personal | Z8: Libre
A9: 7 | B9: 172.17.1.29 | C9: Bernardo Cel | D9: CEL | E9: Personal | Z9: Ocupada
A10: 8 | B10: 172.17.1.30 | C10: ELAP-JBARCENAS | D10: LAP | E10: Institucional | F10: DELL | G10: latitude3420 | H10: / | I10: EC:63:D7:CF:C0:88 | J10: INALÁMBRICO | K10: MANUAL | L10: DRHM | M10: Con/Rest | N10: Sí | P10: Sí | R10: Sí | S10: No | T10: No | U10: Sí | V10: No | W10: Sí | X10: Sí | Z10: Ocupada
A11: 9 | B11: 172.17.1.31 | Z11: Libre
A12: 10 | B12: 172.17.1.32 | C12: msandoval | D12: PC | E12: Institucional | N12: Sí | O12: No | P12: Sí | Q12: no | R12: Sí | S12: No | T12: Sí | U12: Sí | V12: No | W12: Sí | X12: Sí | Y12: solicita navegacion abierta | Z12: Libre
A13: 11 | B13: 172.17.1.33 | C13: Carlos Six | D13: LAP | E13: Personal | F13: HP | J13: INALÁMBRICO | K13: MANUAL | L13: DRHM | M13: Con/Rest | Z13: Ocupada
A14: 12 | B14: 172.17.1.34 | C14: GLAU | Z14: Libre
A15: 13 | B15: 172.17.1.35 | C15: mluna | D15: PC | E15: Institucional | F15: DELL | G15: OPTIPLEX 3080 | H15: / | I15: D0-8E-79-05-23-D1 | J15: INALÁMBRICO | K15: MANUAL | L15: DRHM | M15: Con/Rest | N15: Sí | O15: No | P15: No | Q15: no | R15: No | S15: No | T15: No | U15: Sí | V15: No | W15: Sí | X15: Sí | Y15: Se solicita navegacion abierta | Z15: Ocupada
A16: 14 | B16: 172.17.1.36 | C16: Gelauriano | D16: LAP | E16: Institucional | F16: DELL | H16: / | J16: INALÁMBRICO | K16: MANUAL | L16: DRHM | M16: Con/Rest | N16: Sí | O16: No | P16: No | Q16: no | R16: No | S16: No | T16: No | U16: Sí | V16: no | W16: Sí | X16: Sí | Y16: navegacion abierta | Z16: Libre
A17: 15 | B17: 172.17.1.37 | C17: Salatiel | D17: CEL | E17: Personal | F17: XIAOMI | Z17: Libre
A18: 16 | B18: 172.17.1.38 | C18: lgutierrez/egonzalez | D18: PC | E18: Institucional | F18: DELL | G18: OPTIPLEX 3080 | H18: / | I18: B0:4F:13:01:B2:1A | J18: ALÁMBRICO | K18: MANUAL | L18: DRHM | M18: Con/Rest | N18: Sí | O18: no | P18: no | Q18: no | R18: no | S18: no | T18: no | U18: Sí | V18: no | W18: Sí | X18: No | Z18: Ocupada
A19: 17 | B19: 172.17.1.39 | C19: NMOSKO | D19: LAP | E19: Institucional | F19: DELL | G19: OPTIPLEX 3080 | H19: / | I19: B0-4F-13-01-B2-C2 | J19: ALÁMBRICO | K19: MANUAL | L19: DRHM | M19: Con/Rest | N19: Sí | O19: no | P19: no | Q19: no | R19: no | S19: no | T19: no | U19: Sí | V19: no | W19: Sí | X19: No | Z19: Ocupada
A20: 18 | B20: 172.17.1.40 | C20: jgonzalez | D20: CEL | E20: Personal | F20: SAMSUNG | N20: Sí | O20: no | P20: no | Q20: no | R20: no | S20: no | T20: no | U20: Sí | V20: no | W20: Sí | X20: No | Z20: Ocupada
A21: 19 | B21: 172.17.1.41 | C21: Allison Servicio Social | D21: Cel | E21: Personal | F21: SAMSUNG | G21: Android | J21: INALÁMBRICO | K21: MANUAL | L21: DRHM | M21: Con/Rest | N21: Sí | O21: no | P21: no | Q21: no | R21: no | S21: no | T21: no | U21: Sí | V21: no | W21: Sí | X21: No | Z21: Ocupada
A22: 20 | B22: 172.17.1.42 | C22: JGONZALEZ | Z22: Libre
A23: 21 | B23: 172.17.1.43 | C23: servicio Social Recursos Materiales | D23: CEL | E23: Personal | F23: APPLE | Z23: Ocupada
A24: 22 | B24: 172.17.1.44 | C24: crios | D24: PC | E24: Institucional | F24: DELL | G24: OPTIPLEX 3080 | H24: / | I24: B0-4F-13-01-AF-AD | J24: ALÁMBRICO | K24: MANUAL | L24: DRHM | M24: Con/Rest | N24: Sí | O24: NO | P24: NO | Q24: NO | R24: NO | S24: NO | T24: NO | U24: Sí | V24: NO | W24: Sí | X24: NO | Y24: NAVEGACION ABIERTA | Z24: Ocupada
A25: 23 | B25: 172.17.1.45 | C25: grivera | D25: LAP | E25: Institucional | F25: DELL | G25: latitude3420 | H25: JMLGW93 | I25: 14-85-7F-FF-B6-AD | J25: INALÁMBRICO | K25: MANUAL | L25: DRHM | M25: Sin/Rest | N25: Sí | O25: No | P25: No | R25: No | S25: No | T25: No | U25: Sí | W25: Sí | X25: No | Y25: NAVEGACION ABIERTA | Z25: Ocupada
A26: 24 | B26: 172.17.1.46 | C26: iarriaga | D26: PC | E26: Institucional | F26: DELL | G26: OPTIPLEX 3080 | H26: / | I26: B0-4F-13-00-F9-FA | J26: ALÁMBRICO | K26: MANUAL | L26: DRHM | M26: Con/Rest | N26: Sí | O26: No | R26: No | S26: No | T26: No | U26: Sí | W26: Sí | X26: Sí | Y26: NAVEGACION ABIERTA | Z26: Ocupada
A27: 25 | B27: 172.17.1.47 | C27: Servicio Social 2 | D27: LAP | E27: Institucional | M27: Sin/Rest | Z27: Ocupada
A28: 26 | B28: 172.17.1.48 | C28: AbrahamSandoval | D28: PC | E28: Institucional | F28: DELL | G28: OPTIPLEX 3080 | H28: / | I28: B0-4F-13-01-AE-98 | J28: ALÁMBRICO | K28: MANUAL | L28: DRHM | M28: Con/Rest | N28: Sí | O28: NO | P28: NO | Q28: NO | R28: NO | S28: NO | T28: NO | U28: Sí | V28: NO | W28: Sí | X28: NO | Z28: Ocupada
A29: 27 | B29: 172.17.1.49 | C29: BMARTINEZ | D29: LAP | E29: Institucional | Z29: Libre
A30: 28 | B30: 172.17.1.50 | C30: Alejandra (sin color) | D30: CEL | E30: Personal | F30: APPLE | G30: Iphone 12 | Z30: Libre
A31: 29 | B31: 172.17.1.51 | C31: servicio Social Recursos Materiales | D31: CEL | E31: Personal | F31: SAMSUNG | Z31: Ocupada
A32: 30 | B32: 172.17.1.52 | C32: SERVICIO SOCIAL 1 (PERSONAL) | D32: LAP | E32: Institucional | F32: DELL | N32: Sí | O32: NO | P32: NO | Q32: NO | R32: NO | S32: NO | T32: NO | U32: Sí | V32: NO | W32: Sí | X32: NO | Z32: Ocupada
A33: 31 | B33: 172.17.1.53 | C33: Sindicato | D33: PC | E33: Institucional | J33: INALÁMBRICO | K33: MANUAL | Z33: Ocupada
A34: 32 | B34: 172.17.1.54 | C34: Diego | D34: CEL | E34: Personal | L34: DCS | Z34: Ocupada
A35: 33 | B35: 172.17.1.55 | C35: Jessica Barcenas | D35: LAP | E35: Institucional | F35: DELL | J35: INALÁMBRICO | K35: MANUAL | L35: DEC | Z35: Ocupada
A36: 34 | B36: 172.17.1.56 | C36: Bernardo Guillen | D36: PC | E36: Institucional | F36: DELL | Z36: Ocupada
A37: 35 | B37: 172.17.1.57 | Z37: Libre
A38: 36 | B38: 172.17.1.58 | C38: Yao Cruz | D38: LAP | E38: Institucional | F38: DELL | G38: latitude3420 | H38: / | I38: 14:85:7F:FE:8C:1A | J38: INALÁMBRICO | K38: MANUAL | L38: DRHM | M38: Con/Rest | N38: Sí | O38: no | P38: no | Q38: no | R38: no | S38: no | T38: no | U38: Sí | V38: no | W38: Sí | X38: Sí | Y38: solicita navegacion abierts | Z38: Ocupada
A39: 37 | B39: 172.17.1.59 | C39: Servicio Social 1 | D39: LAP | E39: Institucional | F39: DELL | G39: latitude3420 | J39: INALÁMBRICO | K39: MANUAL | N39: Sí | O39: no | P39: Sí | Q39: no | R39: no | S39: no | T39: Sí | U39: Sí | V39: no | W39: Sí | X39: Sí | Y39: solicita navegacion abierts | Z39: Ocupada
A40: 38 | B40: 172.17.1.60 | C40: g rivera | D40: CEL | E40: Personal | Y40: solicitar navegación abierta | Z40: Libre
...

Sheet DCS
A1: =RANGO!E12 -> DIRECCIÓN DE COMUNICACIÓN SOCIAL
A2: No. | B2: IP | C2: Usuario o nombre del propietario | D2: Tipo de equipo | E2: Institucional o Personal | F2: Marca | G2: modelo | H2: Número de Serie | I2: MAC | J2: Tipo de Conexión | K2: Confguración de red | L2: Área | M2: Restricciones | N2: YOUTUBE | O2: VIMEO | P2: SPOTIFY | Q2: OTRO STREAMING | R2: FACEBOOK | S2: TIK TOK | T2: INSTAGRAM | U2: WHATSAPP WEB | V2: OTRA RED SOCIAL | W2: SITIOS GUBERNAMENTALES | X2: NOTICIAS | Y2: OTRO | Z2: Estatus | AA2: OBSERVACIONES
A3: 1 | B3: 172.17.1.104 | C3: Guadalupe Pimentel | D3: PC | Z3: Libre
A4: 2 | B4: 172.17.1.105 | C4: RLUNA | D4: LAP | E4: Institucional | F4: DELL | G4: latitude3420 | H4: / | I4: 94:E2:3C:00:E9:7A | J4: INALÁMBRICO | K4: MANUAL | L4: DCS | M4: Sin/Rest | N4: Sí | O4: No | P4: NO | Q4: NO | R4: Sí | S4: Sí | T4: Sí | U4: Sí | V4: NO | W4: SÍ | X4: SÍ | Y4: X | Z4: Ocupada
A5: 3 | B5: 172.17.1.106 | C5: Hazzel 2 | D5: CEL | E5: Personal | Z5: Ocupada
A6: 4 | B6: 172.17.1.107 | C6: RCALLEJA | D6: LAP | E6: Institucional | F6: DELL | L6: DCS | M6: Con/Rest | N6: Sí | O6: No | P6: NO | Q6: NO | R6: Sí | S6: Sí | T6: Sí | U6: Sí | V6: NO | W6: Sí | X6: Sí | Y6: SINC y COMSOC | Z6: Ocupada
A7: 5 | B7: 172.17.1.108 | C7: Monserrat Molina | D7: TABLET | E7: Personal | F7: APPLE | L7: DCS | M7: Con/Rest | N7: Sí | O7: No | P7: No | Q7: NO | R7: Sí | S7: Sí | T7: Sí | U7: Sí | V7: NO | W7: Sí | X7: Sí | Y7: REPOSITORIOS, BANCOS DE IMAGENES Y VIDEOS, PINTEREST | Z7: Ocupada
A8: 6 | B8: 172.17.1.109 | C8: jchavira | D8: CEL | E8: Personal | F8: APPLE | L8: DCS | M8: Con/Rest | N8: Sí | O8: No | P8: No | Q8: NO | R8: Sí | S8: Sí | T8: Sí | U8: Sí | V8: X | W8: Sí | X8: Sí | Y8: NO | Z8: Libre
A9: 7 | B9: 172.17.1.110 | C9: RCALLEJA | D9: CEL | E9: Personal | F9: SAMSUNG | L9: DCS | M9: Con/Rest | N9: Sí | O9: No | P9: NO | Q9: NO | R9: Sí | S9: Sí | T9: Sí | U9: Sí | V9: NO | W9: Sí | X9: Sí | Y9: SINC y COMSOC | Z9: Libre
A10: 8 | B10: 172.17.1.111 | C10: ELAP-KFLORES | D10: LAP | E10: Institucional | F10: DELL | G10: latitude3420 | H10: / | I10: 94-E2-3C-26-0D-D1 | J10: INALÁMBRICO | K10: MANUAL | L10: DCS | M10: Con/Rest | N10: No | O10: No | P10: No | Q10: NO | R10: No | S10: NO | T10: No | U10: Sí | V10: NO | W10: Sí | X10: Sí | Y10: NO | Z10: Ocupada
A11: 9 | B11: 172.17.1.112 | C11: DBALDERRAMA | K11: MANUAL | L11: DCS | N11: Sí | O11: No | P11: No | Q11: NO | R11: Sí | S11: Sí | T11: Sí | U11: Sí | V11: NO | W11: Sí | X11: Sí | Y11: REPOSITORIOS, BANCOS DE IMAGENES Y VIDEOS, PINTEREST | Z11: Libre
A12: 10 | B12: 172.17.1.113 | C12: Hazzel | D12: CEL | E12: Personal | F12: OTRO | Z12: Ocupada
A13: 11 | B13: 172.17.1.114 | C13: MRAMIREZ | D13: PC | E13: Institucional | F13: DELL | G13: latitude3420 | L13: DCS | N13: Sí | O13: No | P13: NO | R13: NO | S13: NO | T13: NO | U13: Sí | V13: NO | W13: Sí | X13: Sí | Y13: NO | Z13: Ocupada | AA13: dirección General
A14: 12 | B14: 172.17.1.115 | C14: Nitza | D14: LAP | E14: Personal | F14: APPLE | Z14: Ocupada
A15: 13 | B15: 172.17.1.116 | C15: LZavala | D15: PC | E15: Institucional | F15: DELL | G15: OPTIPLEX 7090 | Z15: Libre
A16: 14 | B16: 172.17.1.117 | C16: Natalia ss | D16: TABLET | E16: Personal | Z16: Libre
A17: 15 | B17: 172.17.1.118 | C17: EPC-YHERNANDEZ | D17: PC | E17: Institucional | F17: DELL | G17: OPTIPLEX 3080 | H17: / | I17: D0-8E-79-05-23-26 | J17: ALÁMBRICO | K17: MANUAL | L17: DCS | M17: Con/Rest | N17: Sí | O17: Sí | P17: Sí | Q17: NO | R17: Sí | S17: Sí | T17: Sí | U17: Sí | V17: NO | W17: Sí | X17: Sí | Y17: NO | Z17: Ocupada
A18: 16 | B18: 172.17.1.119 | C18: layla manilla hernandez | D18: CEL | E18: Personal | F18: APPLE | Z18: Libre
A19: 17 | B19: 172.17.1.120 | C19: Guadalupe | D19: LAP | E19: Institucional | F19: DELL | L19: DCS | M19: Con/Rest | N19: Sí | O19: No | P19: no | Q19: no | R19: No | S19: no | T19: No | U19: Sí | V19: no | W19: Sí | X19: Sí | Y19: no | Z19: Ocupada
A20: 18 | B20: 172.17.1.121 | C20: claudia gonzalez | D20: PC | E20: Institucional | F20: DELL | L20: DCS | M20: Con/Rest | N20: No | O20: No | P20: No | Q20: no | R20: No | S20: No | T20: No | U20: Sí | V20: no | W20: Sí | X20: Sí | Y20: validadciones SAT | Z20: Ocupada
A21: 19 | B21: 172.17.1.122 | C21: Andres Chavira | D21: LAP | E21: Institucional | F21: DELL | G21: latitude3420 | H21: / | Z21: Libre
A22: 20 | B22: 172.17.1.123 | C22: DBALDERRAMA | D22: LAP | E22: Institucional | F22: DELL | L22: DCS | M22: Con/Rest | N22: Sí | O22: No | P22: No | Q22: NO | R22: Sí | S22: Sí | T22: Sí | U22: Sí | V22: NO | W22: Sí | X22: Sí | Y22: NO | Z22: Ocupada
A23: 21 | B23: 172.17.1.124 | C23: ELAP-VSOTO | D23: LAP | E23: Institucional | F23: DELL | G23: latitude3420 | H23: / | I23: 14-85-7F-FF-CB-B6 | J23: ALÁMBRICO | K23: MANUAL | L23: DCS | M23: Con/Rest | N23: Sí | O23: No | P23: no | Q23: no | R23: Sí | S23: Sí | T23: Sí | U23: Sí | V23: x | W23: Sí | X23: Sí | Y23: no | Z23: Ocupada
A24: 22 | B24: 172.17.1.125 | C24: fernanda casique | D24: CEL | E24: Personal | F24: APPLE | Z24: Libre
A25: 23 | B25: 172.17.1.126 | C25: Nitza | D25: CEL | E25: Personal | F25: APPLE | L25: DCS | Z25: Libre
A26: 24 | B26: 172.17.1.127 | C26: Acerecedo | D26: lap | E26: Personal | F26: APPLE | G26: macbook air | Z26: Libre
A27: 25 | B27: 172.17.1.128 | C27: SS | D27: lap | E27: Personal | F27: APPLE | G27: macbook air | Z27: Libre
A28: 26 | B28: 172.17.1.129 | C28: Isaac SANCHEZ | D28: LAP | E28: Personal | F28: honor | Z28: Libre
A29: 27 | B29: 172.17.1.130 | C29: elap-jchavira | D29: LAP | E29: Institucional | F29: DELL | Z29: Libre
A30: 28 | B30: 172.17.1.131 | C30: JUAN | D30: LAP | E30: Personal | L30: DCS | Z30: Libre
A31: 29 | B31: 172.17.1.132 | C31: Brenda Servicio | D31: LAP | E31: Personal | F31: APPLE | Z31: Libre
A32: 30 | B32: 172.17.1.133 | C32: Hazzel | D32: pc | E32: Institucional | F32: DELL | G32: OPTIPLEX 7090 | Z32: Libre
A33: 31 | B33: 172.17.1.134 | C33: Sofía Garcia | D33: TABLET | E33: Personal | F33: APPLE | Z33: Libre
A34: 32 | B34: 172.17.1.135 | C34: CLAUDIA gonzalez | D34: CEL | E34: Personal | L34: DCS | M34: Con/Rest | N34: No | O34: No | P34: No | Q34: no | R34: No | S34: No | T34: No | U34: Sí | V34: no | W34: Sí | X34: Sí | Y34: validadciones SAT | Z34: Libre
A35: 33 | B35: 172.17.1.136 | C35: gen1/Maria de Pilar Blancas | D35: LAP | E35: Institucional | F35: DELL | H35: / | J35: INALÁMBRICO | K35: MANUAL | L35: DCS | M35: Sin/Rest | Z35: Ocupada | AA35: Equipos de Damian
A36: 34 | B36: 172.17.1.137 | C36: alado impresora | D36: PC | E36: Institucional | F36: DELL | G36: OPTIPLEX 7090 | Z36: Libre
A37: 35 | B37: 172.17.1.138 | C37: Claudia Lira | D37: CEL | E37: Personal | F37: OTRO | G37: / | H37: / | I37: / | J37: INALÁMBRICO | K37: MANUAL | L37: DCS | M37: Sin/Rest | Z37: Ocupada | AA37: Finanzas
A38: 36 | B38: 172.17.1.139 | C38: FERNANDA | D38: TABLET | E38: Personal | Z38: Libre
A39: 37 | B39: 172.17.1.140 | C39: Puede que este ocupada | D39: CEL | E39: Personal | F39: APPLE | J39: INALÁMBRICO | K39: MANUAL | L39: DCS | M39: Sin/Rest | N39: Sí | O39: Sí | P39: Sí | Q39: Sí | R39: Sí | S39: Sí | T39: Sí | U39: Sí | V39: Sí | W39: Sí | X39: Sí | Y39: Sí | Z39: Ocupada
A40: 38 | B40: 172.17.1.141 | C40: Pamela LLACA | D40: CEL | E40: Personal | F40: APPLE | G40: macbook air | J40: INALÁMBRICO | K40: MANUAL | L40: DCS | M40: Con/Rest | N40: Sí | O40: No | P40: No | Q40: no | R40: Sí | S40: Sí | T40: Sí | U40: Sí | V40: no | W40: Sí | X40: Sí | Y40: no | Z40: Ocupada
...

Sheet OIC
A1: =RANGO!E13 -> TITULAR DE AUDITORIA INTERNA Y QUEJAS
A2: No. | B2: IP | C2: Usuario o nombre del propietario | D2: Tipo de equipo | E2: Institucional o Personal | F2: Marca | G2: modelo | H2: Número de Serie | I2: MAC | J2: Tipo de Conexión | K2: Confguración de red | L2: Área | M2: Restricciones | N2: YOUTUBE | O2: VIMEO | P2: SPOTIFY | Q2: OTRO STREAMING | R2: FACEBOOK | S2: TIK TOK | T2: INSTAGRAM | U2: WHATSAPP WEB | V2: OTRA RED SOCIAL | W2: SITIOS GUBERNAMENTALES | X2: NOTICIAS | Y2: OTRO | Z2: Estatus | AA2: OBSERVACIONES
A3: 1 | B3: 172.17.1.143 | C3: Servicio Social Comunicación | Z3: Libre
A4: 2 | B4: 172.17.1.144 | Z4: Libre
A5: 3 | B5: 172.17.1.145 | Z5: Libre
A6: 4 | B6: 172.17.1.146 | Z6: Libre
A7: 5 | B7: 172.17.1.147 | C7: EPC-SONATE | D7: PC | E7: Institucional | F7: DELL | G7: OPTIPLEX 3080 | H7: 8DB2FF3 | I7: B0-4F-13-01-B2-9D | J7: ALÁMBRICO | K7: MANUAL | L7: OIC | M7: Con/Rest | Z7: Ocupada
A8: 6 | B8: 172.17.1.148 | C8: epc-ecortes | D8: PC | E8: Institucional | F8: DELL | G8: OPTIPLEX 3080 | H8: 8MKYDF3 | I8: B0:4F:13:00:FA:B5 | J8: ALÁMBRICO | K8: MANUAL | L8: OIC | M8: Con/Rest | Z8: Ocupada
A9: 7 | B9: 172.17.1.149 | Z9: Libre
A10: 8 | B10: 172.17.1.150 | C10: EPC-MCHAVEZ | D10: PC | E10: Institucional | F10: DELL | G10: OPTIPLEX 3080 | H10: / | I10: B0-4F-13-01-B2-98 | J10: ALÁMBRICO | K10: MANUAL | L10: OIC | M10: Con/Rest | Z10: Ocupada
A11: 9 | B11: 172.17.1.151 | C11: Eduardo Vargas | D11: CEL | E11: Personal | Z11: Ocupada
A12: 10 | B12: 172.17.1.152 | C12: Servicio social aREC. materiales | D12: LAP | E12: Personal | F12: DELL | G12: Latitude | Z12: Libre
A13: 11 | B13: 172.17.1.153 | C13: Romina 2 servicio social | Z13: Libre
A14: 12 | B14: 172.17.1.154 | Z14: Libre
A15: 13 | B15: 172.17.1.155 | Z15: Libre
A16: 14 | B16: 172.17.1.156 | C16: Romina Servicio social | Z16: Libre
A17: 15 | B17: 172.17.1.157 | C17: guillermo vigilancia | Z17: Libre
A18: 16 | B18: 172.17.1.158 | Z18: Libre
A19: 17 | B19: 172.17.1.159 | Z19: Libre
A20: 18 | B20: 172.17.1.160 | C20: Carlos DG de Venancio | Z20: Libre
D22: IP´s | E22: LIBRE | F22: OCUPADA | G22: CONFLICTO | H22: TOTAL | J22: IP´s | K22: Con restricciones | M22: Sin restricciones
E23: =COUNTIF($Z$3:$Z$20,DATOS!O2) -> 14 | F23: =COUNTIF($Z$3:$Z$20,DATOS!O3) -> 4 | G23: =COUNTIF($Z$3:$Z$20,DATOS!O4) -> 0 | H23: =SUM(E23:G23) -> 18 | K23: =COUNTIF(M3:$M$20,DATOS!Q2) -> 3 | M23: =COUNTIF($M3:$M$20,DATOS!Q3) -> 0
D25: CONEXIONES | E25: =DATOS!G2 -> INALÁMBRICO | F25: =DATOS!G3 -> ALÁMBRICO | G25: =DATOS!G4 -> ALÁMBRICO/INALÁMBRICO | J25: REGRESAR A LA PESTALLA PRINCIPAL
E26: =COUNTIF(J3:$J$20,DATOS!G2) -> 0 | F26: =COUNTIF(J3:J20,DATOS!G3) -> 3 | G26: =COUNTIF($J3:$J$20,DATOS!G4) -> 0

Sheet SS
A1: =RANGO!E14 -> SUBDIRECCIÓN DE SISTEMAS
A2: No. | B2: IP | C2: Usuario o nombre del propietario | D2: Tipo de equipo | E2: Institucional o Personal | F2: Marca | G2: modelo | H2: Número de Serie | I2: MAC | J2: Tipo de Conexión | K2: Confguración de red | L2: Área | M2: Restricciones | N2: YOUTUBE | O2: VIMEO | P2: SPOTIFY | Q2: OTRO STREAMING | R2: FACEBOOK | S2: TIK TOK | T2: INSTAGRAM | U2: WHATSAPP WEB | V2: OTRA RED SOCIAL | W2: SITIOS GUBERNAMENTALES | X2: NOTICIAS | Y2: OTRO | Z2: Estatus | AA2: OBSERVACIONES
A3: 1 | B3: 172.17.1.161 | C3: Marianne | D3: LAP | E3: Personal | F3: DELL | Z3: Ocupada
A4: 2 | B4: 172.17.1.162 | C4: Mini Servidor | D4: PC | E4: Institucional | F4: HP | G4: HP ProLiant MicroServer Gen8 | Z4: Ocupada
A5: 3 | B5: 172.17.1.163 | C5: yrodriguez | D5: CEL | E5: Personal | F5: OTRO | G5: / | H5: / | I5: / | J5: INALÁMBRICO | K5: MANUAL | L5: SS | M5: Con/Rest | Z5: Ocupada
A6: 4 | B6: 172.17.1.164 | C6: Pau pau compu | Z6: Ocupada
A7: 5 | B7: 172.17.1.165 | C7: Windows 10 del Mini Servidor | D7: PC | E7: Institucional | F7: HP | Z7: Ocupada
A8: 6 | B8: 172.17.1.166 | Z8: Libre
A9: 7 | B9: 172.17.1.167 | Z9: Ocupada
A10: 8 | B10: 172.17.1.168 | C10: EPC-LGOMEZ | D10: PCA | E10: Institucional | F10: DELL | G10: OPTIPLEX 3080 | H10: / | I10: B0-4F-13-01-B2-7C | J10: ALÁMBRICO | K10: MANUAL | L10: SS | M10: Con/Rest | Z10: Ocupada
A11: 9 | B11: 172.17.1.169 | C11: lgomez | D11: CEL | E11: Personal | F11: HUAWEI | G11: P30 | H11: AGTDU19B26000182 | I11: 28:33:34:7A:04:29 | J11: INALÁMBRICO | K11: MANUAL | L11: SS | M11: Con/Rest | Z11: Ocupada
A12: 10 | B12: 172.17.1.170 | C12: Evelyn Venancio | D12: CEL | E12: Personal | F12: APPLE | J12: INALÁMBRICO | K12: MANUAL | L12: SS | Z12: Ocupada
A13: 11 | B13: 172.17.1.171 | C13: Hija de Liz | Z13: Ocupada
A14: 12 | B14: 172.17.1.172 | C14: Lulú Lap | D14: LAP | E14: Institucional | F14: DELL | G14: latitude3420 | Z14: Ocupada
A15: 13 | B15: 172.17.1.173 | Z15: Ocupada | AA15: RH
A16: 14 | B16: 172.17.1.174 | Z16: Ocupada
A17: 15 | B17: 172.17.1.175 | C17: yrodriguez | D17: PC | E17: Institucional | F17: DELL | G17: OPTIPLEX 7090 | H17: / | I17: D0-8E-79-05-23-1E | J17: ALÁMBRICO | K17: MANUAL | L17: SS | M17: Con/Rest | Z17: Ocupada
A18: 16 | B18: 172.17.1.176 | C18: erick lara | D18: LAP | E18: Personal | F18: APPLE | G18: Macbook pro | Z18: Ocupada
A19: 17 | B19: 172.17.1.177 | Z19: Ocupada
A20: 18 | B20: 172.17.1.178 | C20: Evelyn Venancio | D20: LAP | E20: Institucional | F20: DELL | G20: latitude3420 | J20: INALÁMBRICO | K20: MANUAL | L20: SS | M20: Sin/Rest | Z20: Ocupada
A21: 19 | B21: 172.17.1.179 | Z21: Ocupada
A22: 20 | B22: 172.17.1.180 | C22: PC-octavio | D22: PC | E22: Institucional | F22: DELL | G22: OPTIPLEX 7090 | H22: / | I22: D0-8E-79-05-23-AA | J22: ALÁMBRICO | K22: MANUAL | L22: SS | M22: Sin/Rest | Z22: Ocupada
A23: 21 | B23: 172.17.1.181 | C23: Capacitación (Sigales) | D23: IMPRESORA | E23: Institucional | F23: LEXMARK | G23: CS725 | H23: 50282430H69PZ | J23: ALÁMBRICO | K23: MANUAL | L23: DRHM | M23: Con/Rest | Z23: Libre
A24: 22 | B24: 172.17.1.182 | Z24: Ocupada
A25: 23 | B25: 172.17.1.183 | Z25: Libre
A26: 24 | B26: 172.17.1.184 | C26: Jessica sigales | D26: LAP | E26: Institucional | L26: DRHM | Z26: Ocupada
A27: 25 | B27: 172.17.1.185 | C27: erick lara | D27: cel | E27: Personal | F27: APPLE | Z27: Ocupada
A28: 26 | B28: 172.17.1.186 | Z28: Ocupada
A29: 27 | B29: 172.17.1.187 | C29: Octavio Cel | D29: CEL | E29: Personal | F29: APPLE | G29: Iphone 13 | Z29: Ocupada
